<?xml version="1.0" ?>
<!-- =================================================================================== -->
<!-- |    This document was autogenerated by xacro from use_case_setup_robelix_mobile.urdf.xacro | -->
<!-- |    EDITING THIS FILE BY HAND IS NOT RECOMMENDED                                 | -->
<!-- =================================================================================== -->
<robot name="robelix_neura_robot">
  <!-- prefix should be used for all links and joints so that it actually works. Also prefix has to be applied inside the <insert_ros_param> macro! -->
  <!-- <xacro:property name="prefix" value="maira7M_" /> -->
  <!-- rubber -->
  <material name="rubber">
    <color rgba="0.15294117647058825 0.15294117647058825 0.15294117647058825 1.0"/>
  </material>
  <!-- aluminium_satin -->
  <material name="aluminium_satin">
    <color rgba="0.9607843137254902 0.9607843137254902 0.9647058823529412 1.0"/>
  </material>
  <!-- pulver_black -->
  <material name="pulver_black">
    <color rgba="0.09803921568627451 0.09803921568627451 0.09803921568627451 1.0"/>
  </material>
  <!-- led_blue -->
  <material name="led_blue">
    <color rgba="0.1 0.85 1.0 1"/>
  </material>
  <!-- plastic_glossy_black -->
  <material name="plastic_glossy_black">
    <color rgba="0.09803921568627451 0.09803921568627451 0.09803921568627451 1.0"/>
  </material>
  <!-- plastic_glossy_white -->
  <material name="plastic_glossy_white">
    <color rgba="1.0 1.0 1.0 1.0"/>
  </material>
  <gazebo reference="mav_laser_left_link">
    <sensor name="mav_laser_left_link" type="ray">
      <always_on>true</always_on>
      <visualize>true</visualize>
      <update_rate>10.0</update_rate>
      <ray>
        <scan>
          <horizontal>
            <samples>500</samples>
            <resolution>1</resolution>
            <min_angle>-2.281</min_angle>
            <max_angle>2.225</max_angle>
          </horizontal>
        </scan>
        <range>
          <min>0.05</min>
          <max>10.0</max>
          <resolution>0.01</resolution>
        </range>
        <noise>
          <type>gaussian</type>
          <mean>0.0</mean>
          <stddev>0.006</stddev>
        </noise>
      </ray>
      <plugin filename="libgazebo_ros_ray_sensor.so" name="mav_laser_left_link_plugin">
        <ros>
          <remapping>~/out:=scan_left</remapping>
        </ros>
        <output_type>sensor_msgs/LaserScan</output_type>
        <frame_name>mav_laser_left_link</frame_name>
      </plugin>
    </sensor>
  </gazebo>
  <gazebo reference="mav_laser_right_link">
    <sensor name="mav_laser_right_link" type="ray">
      <always_on>true</always_on>
      <visualize>true</visualize>
      <update_rate>10.0</update_rate>
      <ray>
        <scan>
          <horizontal>
            <samples>540</samples>
            <resolution>1</resolution>
            <min_angle>-2.281</min_angle>
            <max_angle>2.225</max_angle>
          </horizontal>
        </scan>
        <range>
          <min>0.05</min>
          <max>10.0</max>
          <resolution>0.01</resolution>
        </range>
        <noise>
          <type>gaussian</type>
          <mean>0.0</mean>
          <stddev>0.006</stddev>
        </noise>
      </ray>
      <plugin filename="libgazebo_ros_ray_sensor.so" name="mav_laser_right_link_plugin">
        <ros>
          <remapping>~/out:=scan_right</remapping>
        </ros>
        <output_type>sensor_msgs/LaserScan</output_type>
        <frame_name>mav_laser_right_link</frame_name>
      </plugin>
    </sensor>
  </gazebo>
  <gazebo>
    <!-- <plugin name="gazebo_ros_state" filename="libgazebo_ros_state.so">
                <ros>
                <namespace>/gazebo</namespace>
                </ros>
                <update_rate>1.0</update_rate>
            </plugin> -->
    <plugin filename="libgazebo_ros_diff_drive.so" name="diff_drive">
      <ros>
        <!-- <namespace>/demo</namespace> -->
      </ros>
      <!-- <update_rate>30</update_rate> -->
      <left_joint>mav_joint_wheel_l</left_joint>
      <right_joint>mav_joint_wheel_r</right_joint>
      <wheel_separation>0.63</wheel_separation>
      <wheel_diameter>0.2</wheel_diameter>
      <max_wheel_torque>20</max_wheel_torque>
      <max_wheel_acceleration>1.0</max_wheel_acceleration>
      <command_topic>cmd_vel</command_topic>
      <publish_odom>true</publish_odom>
      <publish_odom_tf>true</publish_odom_tf>
      <publish_wheel_tf>true</publish_wheel_tf>
      <robot_base_frame>mav_base_link</robot_base_frame>
    </plugin>
  </gazebo>
  <!-- Compensate for X-Axis not in front -->
  <link name="mav_base_link">
    <inertial>
      <!-- <origin rpy="0 0 0" xyz="0 0.012821565140168243 0.13322429405501768"/> -->
      <origin rpy="0 0 0" xyz="0 0 0.13322429405501768"/>
      <!-- <mass value="82.06100813777122"/> -->
      <mass value="400"/>
      <!-- TODO this is a temporary hack and the interia parameters to not fit the mass -->
      <inertia ixx="7.240809" ixy="0" ixz="0" iyy="16.506698" iyz="0" izz="22.103898"/>
    </inertial>
    <visual>
      <origin rpy="0 0 1.5707963267948966" xyz="0 0 0"/>
      <geometry>
        <mesh filename="package://mav_description/urdf/mav/meshes/visual/base_link.dae" scale="0.001 0.001 0.001"/>
      </geometry>
    </visual>
    <!-- <visual>
            <origin rpy="0 0 0" xyz="0 0 0"/>
            <geometry>
            <mesh filename="package://mav_description/urdf/mav/meshes/visual/mav_buttons.obj" scale="0.1 0.1 0.1"/>
            </geometry>
        </visual> -->
    <collision>
      <origin rpy="0 0 1.5707963267948966" xyz="0 0 0"/>
      <geometry>
        <mesh filename="package://mav_description/urdf/mav/meshes/collision/base_link.stl" scale="0.001 0.001 0.001"/>
      </geometry>
    </collision>
  </link>
  <link name="mav_laser_left_link">
    <inertial>
      <origin rpy="0 0 0" xyz="-7.318782055543149e-05 -6.051029392106777e-06 -0.016939766798375694"/>
      <mass value="4.65131897885331"/>
      <inertia ixx="0.005565" ixy="8e-06" ixz="7e-06" iyy="0.005544" iyz="1.1e-05" izz="0.006353"/>
    </inertial>
    <visual>
      <origin rpy="0 0 0" xyz="-0.38002 -0.675306 -0.113837"/>
      <geometry>
        <mesh filename="package://mav_description/urdf/mav/meshes/visual/laser_left_link.dae" scale="0.001 0.001 0.001"/>
      </geometry>
    </visual>
    <!-- <collision>
            <origin rpy="0 0 0" xyz="-0.38002 -0.675306 -0.113837"/>
            <geometry>
            <mesh filename="package://mav_description/urdf/mav/meshes/visual/laser_left_link.dae" scale="0.001 0.001 0.001"/>
            </geometry>
        </collision> -->
  </link>
  <link name="mav_laser_right_link">
    <inertial>
      <origin rpy="0 0 0" xyz="7.285773476484181e-05 6.720943503180088e-06 -0.01693976679838556"/>
      <mass value="4.65131897885331"/>
      <inertia ixx="0.005565" ixy="8e-06" ixz="-7e-06" iyy="0.005544" iyz="-1.1e-05" izz="0.006353"/>
    </inertial>
    <visual>
      <origin rpy="0 0 0" xyz="0.38055 0.675837 -0.113837"/>
      <geometry>
        <mesh filename="package://mav_description/urdf/mav/meshes/visual/laser_right_link.dae" scale="0.001 0.001 0.001"/>
      </geometry>
    </visual>
    <!-- <collision>
            <origin rpy="0 0 0" xyz="0.38055 0.675837 -0.113837"/>
            <geometry>
            <mesh filename="package://mav_description/urdf/mav/meshes/visual/laser_right_link.dae" scale="0.001 0.001 0.001"/>
            </geometry>
        </collision> -->
  </link>
  <joint name="mav_joint_laser_l" type="fixed">
    <origin rpy="0 0 5.4977863267948965" xyz="0.675837 -0.38055 0.113837"/>
    <parent link="mav_base_link"/>
    <child link="mav_laser_left_link"/>
  </joint>
  <joint name="mav_joint_laser_r" type="fixed">
    <origin rpy="0 0 2.3561963267948967" xyz="-0.675306 0.38002 0.113837"/>
    <parent link="mav_base_link"/>
    <child link="mav_laser_right_link"/>
  </joint>
  <link name="mav_cover_left_link">
    <!-- <inertial>
          <origin rpy="0 0 0" xyz="0.4195968335880831 0.0001881607967491469 0.13492114775978598"/>
          <mass value="0.9859363981049758"/>
          <inertia ixx="0.232108" ixy="-1.6e-05" ixz="0.000289" iyy="0.01081" iyz="-8.4e-05" izz="0.223203"/>
        </inertial> -->
    <visual>
      <origin rpy="0 0 1.5707963267948966" xyz="-0.0 -0.0 -0.025491"/>
      <geometry>
        <mesh filename="package://mav_description/urdf/mav/meshes/visual/cover_left_link.stl" scale="0.001 0.001 0.001"/>
      </geometry>
      <material name="plastic_glossy_black"/>
    </visual>
    <collision>
      <origin rpy="0 0 1.5707963267948966" xyz="-0.0 -0.0 -0.025491"/>
      <geometry>
        <mesh filename="package://mav_description/urdf/mav/meshes/visual/cover_left_link.stl" scale="0.001 0.001 0.001"/>
      </geometry>
    </collision>
  </link>
  <link name="mav_cover_right_link">
    <!-- <inertial>
          <origin rpy="0 0 0" xyz="-0.4195968227349081 -0.00018833859725122168 0.1349211478696426"/>
          <mass value="0.9859366459141587"/>
          <inertia ixx="0.232108" ixy="-1.6e-05" ixz="-0.000289" iyy="0.01081" iyz="8.4e-05" izz="0.223203"/>
        </inertial> -->
    <visual>
      <origin rpy="0 0 1.5707963267948966" xyz="-0.0 -0.0 -0.025491"/>
      <geometry>
        <mesh filename="package://mav_description/urdf/mav/meshes/visual/cover_right_link.stl" scale="0.001 0.001 0.001"/>
      </geometry>
      <material name="plastic_glossy_black"/>
    </visual>
    <collision>
      <origin rpy="0 0 1.5707963267948966" xyz="-0.0 -0.0 -0.025491"/>
      <geometry>
        <mesh filename="package://mav_description/urdf/mav/meshes/visual/cover_right_link.stl" scale="0.001 0.001 0.001"/>
      </geometry>
    </collision>
  </link>
  <joint name="mav_joint_cl" type="fixed">
    <origin rpy="0 0 0" xyz="0.0 0.0 0.025491"/>
    <parent link="mav_base_link"/>
    <child link="mav_cover_left_link"/>
  </joint>
  <joint name="mav_joint_cr" type="fixed">
    <origin rpy="0 0 0" xyz="0.0 0.0 0.025491"/>
    <parent link="mav_base_link"/>
    <child link="mav_cover_right_link"/>
  </joint>
  <link name="mav_led_link">
    <!-- <inertial>
            <origin rpy="0 0 0" xyz="2.4714873798595464e-17 7.215825733074473e-16 0.1299999999999999"/>
            <mass value="1.43748"/>
            <inertia ixx="0.176582" ixy="0.0" ixz="0.0" iyy="0.190095" iyz="-0.0" izz="0.364281"/>
        </inertial> -->
    <visual>
      <origin rpy="0 0 0" xyz="-0.0 -0.0 -0.025491"/>
      <geometry>
        <mesh filename="package://mav_description/urdf/mav/meshes/visual/led_link.stl" scale="0.001 0.001 0.001"/>
      </geometry>
      <material name="led_blue"/>
    </visual>
    <collision>
      <origin rpy="0 0 0" xyz="-0.0 -0.0 -0.025491"/>
      <geometry>
        <mesh filename="package://mav_description/urdf/mav/meshes/visual/led_link.stl" scale="0.001 0.001 0.001"/>
      </geometry>
    </collision>
  </link>
  <link name="mav_c_back_led_right">
    <!-- <inertial>
            <origin rpy="0 0 0" xyz="-0.21850000000000017 0.760748778154568 0.13989999999999997"/>
            <mass value="0.06007254110478115"/>
            <inertia ixx="2e-06" ixy="-0.0" ixz="-0.0" iyy="0.00025" iyz="0.0" izz="0.00025"/>
        </inertial> -->
    <visual>
      <origin rpy="0 0 0" xyz="-0.0 -0.0 -0.025491"/>
      <geometry>
        <mesh filename="package://mav_description/urdf/mav/meshes/visual/c_back_led_right.stl" scale="0.001 0.001 0.001"/>
      </geometry>
      <material name="led_blue"/>
    </visual>
    <collision>
      <origin rpy="0 0 0" xyz="-0.0 -0.0 -0.025491"/>
      <geometry>
        <mesh filename="package://mav_description/urdf/mav/meshes/visual/c_back_led_right.stl" scale="0.001 0.001 0.001"/>
      </geometry>
    </collision>
  </link>
  <link name="mav_c_front_led_right">
    <!-- <inertial>
            <origin rpy="0 0 0" xyz="-0.21850000000000008 -0.7607487781545658 0.13989999999999952"/>
            <mass value="0.0600725411047812"/>
            <inertia ixx="2e-06" ixy="0.0" ixz="0.0" iyy="0.00025" iyz="0.0" izz="0.00025"/>
        </inertial> -->
    <visual>
      <origin rpy="0 0 0" xyz="-0.0 -0.0 -0.025491"/>
      <geometry>
        <mesh filename="package://mav_description/urdf/mav/meshes/visual/c_front_led_right.stl" scale="0.001 0.001 0.001"/>
      </geometry>
      <material name="led_blue"/>
    </visual>
    <collision>
      <origin rpy="0 0 0" xyz="-0.0 -0.0 -0.025491"/>
      <geometry>
        <mesh filename="package://mav_description/urdf/mav/meshes/visual/c_front_led_right.stl" scale="0.001 0.001 0.001"/>
      </geometry>
    </collision>
  </link>
  <link name="mav_c_back_led_left">
    <!-- <inertial>
            <origin rpy="0 0 0" xyz="0.21850000000000044 0.760748778154568 0.13990000000000002"/>
            <mass value="0.06007254110478114"/>
            <inertia ixx="2e-06" ixy="0.0" ixz="0.0" iyy="0.00025" iyz="0.0" izz="0.00025"/>
        </inertial> -->
    <visual>
      <origin rpy="0 0 0" xyz="-0.0 -0.0 -0.025491"/>
      <geometry>
        <mesh filename="package://mav_description/urdf/mav/meshes/visual/c_back_led_left.stl" scale="0.001 0.001 0.001"/>
      </geometry>
      <material name="led_blue"/>
    </visual>
    <collision>
      <origin rpy="0 0 0" xyz="-0.0 -0.0 -0.025491"/>
      <geometry>
        <mesh filename="package://mav_description/urdf/mav/meshes/visual/c_back_led_left.stl" scale="0.001 0.001 0.001"/>
      </geometry>
    </collision>
  </link>
  <link name="mav_c_front_display">
    <!-- <inertial>
            <origin rpy="0 0 0" xyz="-2.4004294571514916e-16 -0.7570937187932779 0.19797084563127199"/>
            <mass value="0.2025536997637012"/>
            <inertia ixx="0.000153" ixy="0.0" ixz="-0.0" iyy="0.000472" iyz="-0.0" izz="0.000325"/>
        </inertial> -->
    <visual>
      <origin rpy="0 0 0" xyz="-0.0 -0.0 -0.025491"/>
      <geometry>
        <mesh filename="package://mav_description/urdf/mav/meshes/visual/c_front_display.dae" scale="0.001 0.001 0.001"/>
      </geometry>
      <material name="led_blue"/>
    </visual>
    <collision>
      <origin rpy="0 0 0" xyz="-0.0 -0.0 -0.025491"/>
      <geometry>
        <mesh filename="package://mav_description/urdf/mav/meshes/visual/c_front_display.dae" scale="0.001 0.001 0.001"/>
      </geometry>
    </collision>
  </link>
  <link name="mav_c_front_led_left">
    <!-- <inertial>
            <origin rpy="0 0 0" xyz="0.21849999999999997 -0.7607487781545654 0.13989999999999936"/>
            <mass value="0.0600725411047812"/>
            <inertia ixx="2e-06" ixy="0.0" ixz="-0.0" iyy="0.00025" iyz="0.0" izz="0.00025"/>
        </inertial> -->
    <visual>
      <origin rpy="0 0 0" xyz="-0.0 -0.0 -0.025491"/>
      <geometry>
        <mesh filename="package://mav_description/urdf/mav/meshes/visual/c_front_led_left.stl" scale="0.001 0.001 0.001"/>
      </geometry>
      <material name="led_blue"/>
    </visual>
    <collision>
      <origin rpy="0 0 0" xyz="-0.0 -0.0 -0.025491"/>
      <geometry>
        <mesh filename="package://mav_description/urdf/mav/meshes/visual/c_front_led_left.stl" scale="0.001 0.001 0.001"/>
      </geometry>
      <material name="led_blue"/>
    </collision>
  </link>
  <joint name="mav_joint_led" type="fixed">
    <origin rpy="0 0 1.5707963267948966" xyz="0.0 0.0 0.025491"/>
    <parent link="mav_base_link"/>
    <child link="mav_led_link"/>
  </joint>
  <joint name="mav_joint_led_br" type="fixed">
    <origin rpy="0 0 1.5707963267948966" xyz="0.0 0.0 0.025491"/>
    <parent link="mav_base_link"/>
    <child link="mav_c_back_led_right"/>
  </joint>
  <joint name="mav_joint_led_fr" type="fixed">
    <origin rpy="0 0 1.5707963267948966" xyz="0.0 0.0 0.025491"/>
    <parent link="mav_base_link"/>
    <child link="mav_c_front_led_right"/>
  </joint>
  <joint name="mav_joint_led_bl" type="fixed">
    <origin rpy="0 0 1.5707963267948966" xyz="0.0 0.0 0.025491"/>
    <parent link="mav_base_link"/>
    <child link="mav_c_back_led_left"/>
  </joint>
  <joint name="mav_joint_led_fl" type="fixed">
    <origin rpy="0 0 1.5707963267948966" xyz="0.0 0.0 0.025491"/>
    <parent link="mav_base_link"/>
    <child link="mav_c_front_led_left"/>
  </joint>
  <joint name="mav_joint_display" type="fixed">
    <origin rpy="0 0 1.5707963267948966" xyz="0.0 0.0 0.025491"/>
    <parent link="mav_base_link"/>
    <child link="mav_c_front_display"/>
  </joint>
  <link name="mav_wheel_right_link">
    <inertial>
      <origin rpy="0 0 0" xyz="0 0 0"/>
      <!-- <mass value="3.176670891761916"/> -->
      <mass value="5.0"/>
      <inertia ixx="0.00213" ixy="0.0" ixz="-0.0" iyy="0.001195" iyz="0.0" izz="0.001195"/>
    </inertial>
    <visual>
      <origin rpy="0 1.5708 0" xyz="0 0 0"/>
      <geometry>
        <cylinder length="0.07" radius="0.0865"/>
      </geometry>
      <material name="rubber"/>
    </visual>
    <collision>
      <origin rpy="0 1.5708 0" xyz="0 0 0"/>
      <geometry>
        <cylinder length="0.07" radius="0.0865"/>
      </geometry>
    </collision>
  </link>
  <link name="mav_wheel_left_link">
    <inertial>
      <origin rpy="0 0 0" xyz="0 0 0"/>
      <!-- <mass value="3.176670891761916"/> -->
      <mass value="5.0"/>
      <inertia ixx="0.00213" ixy="0.0" ixz="-0.0" iyy="0.001195" iyz="0.0" izz="0.001195"/>
    </inertial>
    <visual>
      <origin rpy="0 1.5708 0" xyz="0 0 0"/>
      <geometry>
        <cylinder length="0.07" radius="0.0865"/>
      </geometry>
      <material name="rubber"/>
    </visual>
    <collision>
      <origin rpy="0 1.5708 0" xyz="0 0 0"/>
      <geometry>
        <cylinder length="0.07" radius="0.0865"/>
      </geometry>
    </collision>
  </link>
  <link name="mav_caster_base_bl_link">
    <inertial>
      <origin rpy="0 0 0" xyz="-1.4766528064757978e-06 -0.007290070481652866 -0.01879698235044068"/>
      <mass value="0.3817226478209864"/>
      <inertia ixx="0.000293" ixy="-0.0" ixz="-0.0" iyy="0.000264" iyz="-5.9e-05" izz="0.00038"/>
    </inertial>
    <visual>
      <origin rpy="0 0 0" xyz="-0.32125 -0.46625 -0.091491"/>
      <geometry>
        <mesh filename="package://mav_description/urdf/mav/meshes/visual/caster_base_bl_link.stl" scale="0.001 0.001 0.001"/>
      </geometry>
      <material name="aluminium_satin"/>
    </visual>
    <collision>
      <origin rpy="0 0 0" xyz="-0.32125 -0.46625 -0.091491"/>
      <geometry>
        <mesh filename="package://mav_description/urdf/mav/meshes/visual/caster_base_bl_link.stl" scale="0.001 0.001 0.001"/>
      </geometry>
    </collision>
  </link>
  <link name="mav_caster_base_br_link">
    <inertial>
      <origin rpy="0 0 0" xyz="-1.476701755265264e-06 -0.007290070484625655 -0.018796982351533"/>
      <mass value="0.38172264783150434"/>
      <inertia ixx="0.000293" ixy="-0.0" ixz="-0.0" iyy="0.000264" iyz="-5.9e-05" izz="0.00038"/>
    </inertial>
    <visual>
      <origin rpy="0 0 0" xyz="0.32125 -0.46625 -0.091491"/>
      <geometry>
        <mesh filename="package://mav_description/urdf/mav/meshes/visual/caster_base_br_link.stl" scale="0.001 0.001 0.001"/>
      </geometry>
      <material name="aluminium_satin"/>
    </visual>
    <collision>
      <origin rpy="0 0 0" xyz="0.32125 -0.46625 -0.091491"/>
      <geometry>
        <mesh filename="package://mav_description/urdf/mav/meshes/visual/caster_base_br_link.stl" scale="0.001 0.001 0.001"/>
      </geometry>
    </collision>
  </link>
  <link name="mav_caster_base_fr_link">
    <inertial>
      <origin rpy="0 0 0" xyz="-1.476693103297233e-06 -0.0072900704989687926 -0.018796983067774525"/>
      <mass value="0.38172264782964527"/>
      <inertia ixx="0.000293" ixy="-0.0" ixz="-0.0" iyy="0.000264" iyz="-5.9e-05" izz="0.00038"/>
    </inertial>
    <visual>
      <origin rpy="0 0 0" xyz="0.32125 0.46625 -0.091491"/>
      <geometry>
        <mesh filename="package://mav_description/urdf/mav/meshes/visual/caster_base_fr_link.stl" scale="0.001 0.001 0.001"/>
      </geometry>
      <material name="aluminium_satin"/>
    </visual>
    <collision>
      <origin rpy="0 0 0" xyz="0.32125 0.46625 -0.091491"/>
      <geometry>
        <mesh filename="package://mav_description/urdf/mav/meshes/visual/caster_base_fr_link.stl" scale="0.001 0.001 0.001"/>
      </geometry>
    </collision>
  </link>
  <link name="mav_caster_base_fl_link">
    <inertial>
      <origin rpy="0 0 0" xyz="-1.4766528904641696e-06 -0.007290070481654809 -0.018796982350442804"/>
      <mass value="0.3817226478210045"/>
      <inertia ixx="0.000293" ixy="-0.0" ixz="-0.0" iyy="0.000264" iyz="-5.9e-05" izz="0.00038"/>
    </inertial>
    <visual>
      <origin rpy="0 0 0" xyz="-0.32125 0.46625 -0.091491"/>
      <geometry>
        <mesh filename="package://mav_description/urdf/mav/meshes/visual/caster_base_fl_link.stl" scale="0.001 0.001 0.001"/>
      </geometry>
      <material name="aluminium_satin"/>
    </visual>
    <collision>
      <origin rpy="0 0 0" xyz="-0.32125 0.46625 -0.091491"/>
      <geometry>
        <mesh filename="package://mav_description/urdf/mav/meshes/visual/caster_base_fl_link.stl" scale="0.001 0.001 0.001"/>
      </geometry>
    </collision>
  </link>
  <link name="mav_caster_wheel_bl_link">
    <inertial>
      <origin rpy="0 0 0" xyz="3.306622056165054e-07 -1.3205538940130879e-08 5.218378884147556e-07"/>
      <mass value="0.12208379156311495"/>
      <inertia ixx="6.6e-05" ixy="0.0" ixz="-0.0" iyy="5.1e-05" iyz="0.0" izz="5.1e-05"/>
    </inertial>
    <visual>
      <origin rpy="0 1.5708 0" xyz="0 0 0"/>
      <geometry>
        <cylinder length="0.045" radius="0.032207"/>
      </geometry>
      <material name="rubber"/>
    </visual>
    <collision>
      <origin rpy="0 1.5708 0" xyz="0 0 0"/>
      <geometry>
        <cylinder length="0.045" radius="0.032207"/>
      </geometry>
    </collision>
  </link>
  <link name="mav_caster_wheel_br_link">
    <inertial>
      <origin rpy="0 0 0" xyz="3.305630075778332e-07 -1.320747222699481e-08 5.218379027713271e-07"/>
      <mass value="0.12208379156311495"/>
      <inertia ixx="6.6e-05" ixy="0.0" ixz="-0.0" iyy="5.1e-05" iyz="0.0" izz="5.1e-05"/>
    </inertial>
    <visual>
      <origin rpy="0 1.5708 0" xyz="0 0 0"/>
      <geometry>
        <cylinder length="0.045" radius="0.032207"/>
      </geometry>
      <material name="rubber"/>
    </visual>
    <collision>
      <origin rpy="0 1.5708 0" xyz="0 0 0"/>
      <geometry>
        <cylinder length="0.045" radius="0.032207"/>
      </geometry>
    </collision>
  </link>
  <link name="mav_caster_wheel_fl_link">
    <inertial>
      <origin rpy="0 0 0" xyz="3.3066203536380456e-07 -1.320553899564203e-08 5.218378882065888e-07"/>
      <mass value="0.12208379156311495"/>
      <inertia ixx="6.6e-05" ixy="0.0" ixz="-0.0" iyy="5.1e-05" iyz="0.0" izz="5.1e-05"/>
    </inertial>
    <visual>
      <origin rpy="0 1.5708 0" xyz="0 0 0"/>
      <geometry>
        <cylinder length="0.045" radius="0.032207"/>
      </geometry>
      <material name="rubber"/>
    </visual>
    <collision>
      <origin rpy="0 1.5708 0" xyz="0 0 0"/>
      <geometry>
        <cylinder length="0.045" radius="0.032207"/>
      </geometry>
    </collision>
  </link>
  <link name="mav_caster_wheel_fr_link">
    <inertial>
      <origin rpy="0 0 0" xyz="3.3058054105250534e-07 -1.3221999606294332e-08 5.211214656533625e-07"/>
      <mass value="0.12208379156311495"/>
      <inertia ixx="6.6e-05" ixy="0.0" ixz="-0.0" iyy="5.1e-05" iyz="0.0" izz="5.1e-05"/>
    </inertial>
    <visual>
      <origin rpy="0 1.5708 0" xyz="0 0 0"/>
      <geometry>
        <cylinder length="0.045" radius="0.032207"/>
      </geometry>
      <material name="rubber"/>
    </visual>
    <collision>
      <origin rpy="0 1.5708 0" xyz="0 0 0"/>
      <geometry>
        <cylinder length="0.045" radius="0.032207"/>
      </geometry>
    </collision>
  </link>
  <joint name="mav_joint_wheel_r" type="fixed">
    <origin rpy="0 0 1.5707963267948966" xyz="0.0 -0.3125 0.086"/>
    <parent link="mav_base_link"/>
    <child link="mav_wheel_right_link"/>
    <axis xyz="1.0 0.0 0.0"/>
  </joint>
  <joint name="mav_joint_wheel_l" type="fixed">
    <origin rpy="0 0 1.5707963267948966" xyz="0.0 0.3125 0.086"/>
    <parent link="mav_base_link"/>
    <child link="mav_wheel_left_link"/>
    <axis xyz="1.0 0.0 0.0"/>
  </joint>
  <joint name="mav_joint_caster_bl" type="fixed">
    <origin rpy="0 0 1.5707963267948966" xyz="-0.46625 0.32125 0.091491"/>
    <parent link="mav_base_link"/>
    <child link="mav_caster_base_bl_link"/>
    <axis xyz="-0.0 0.0 -1.0"/>
    <dynamics damping="0.01" friction="0.0"/>
  </joint>
  <joint name="mav_joint_caster_br" type="fixed">
    <origin rpy="0 0 1.5707963267948966" xyz="-0.46625 -0.32125 0.091491"/>
    <parent link="mav_base_link"/>
    <child link="mav_caster_base_br_link"/>
    <axis xyz="-0.0 0.0 -1.0"/>
    <dynamics damping="0.01" friction="0.0"/>
  </joint>
  <joint name="mav_joint_caster_fr" type="fixed">
    <origin rpy="0 0 1.5707963267948966" xyz="0.46625 -0.32125 0.091491"/>
    <parent link="mav_base_link"/>
    <child link="mav_caster_base_fr_link"/>
    <axis xyz="-0.0 0.0 -1.0"/>
    <dynamics damping="0.01" friction="0.0"/>
  </joint>
  <joint name="mav_joint_caster_fl" type="fixed">
    <origin rpy="0 0 1.5707963267948966" xyz="0.46625 0.32125 0.091491"/>
    <parent link="mav_base_link"/>
    <child link="mav_caster_base_fl_link"/>
    <axis xyz="-0.0 0.0 -1.0"/>
    <dynamics damping="0.01" friction="0.0"/>
  </joint>
  <joint name="mav_joint_caster_wheel_bl" type="fixed">
    <origin rpy="0 0 0" xyz="0.0 -0.045 -0.05896"/>
    <parent link="mav_caster_base_bl_link"/>
    <child link="mav_caster_wheel_bl_link"/>
    <axis xyz="1.0 0.0 -0.0"/>
  </joint>
  <joint name="mav_joint_caster_wheel_br" type="fixed">
    <origin rpy="0 0 0" xyz="0.0 -0.045 -0.05896"/>
    <parent link="mav_caster_base_br_link"/>
    <child link="mav_caster_wheel_br_link"/>
    <axis xyz="1.0 0.0 -0.0"/>
  </joint>
  <joint name="mav_joint_caster_wheel_fl" type="fixed">
    <origin rpy="0 0 0" xyz="0.0 -0.045 -0.05896"/>
    <parent link="mav_caster_base_fl_link"/>
    <child link="mav_caster_wheel_fl_link"/>
    <axis xyz="1.0 0.0 -0.0"/>
  </joint>
  <joint name="mav_joint_caster_wheel_fr" type="fixed">
    <origin rpy="0 0 0" xyz="0.0 -0.045 -0.05896"/>
    <parent link="mav_caster_base_fr_link"/>
    <child link="mav_caster_wheel_fr_link"/>
    <axis xyz="1.0 0.0 -0.0"/>
  </joint>
  <!-- <xacro:mav /> -->
  <joint name="linear_axis" type="fixed">
    <origin rpy="0 0 0" xyz="0.52 0 0.8125"/>
    <parent link="mav_base_link"/>
    <child link="linear_axis_sled"/>
    <axis xyz="0 0 1"/>
  </joint>
  <link name="linear_axis_sled">
    <visual>
      <origin rpy="0 0 0" xyz="0 0 -0.1825"/>
      <geometry>
        <box size="0.3 0.55 0.365"/>
      </geometry>
      <material name="plastic_glossy_white"/>
    </visual>
    <collision>
      <origin rpy="0 0 0" xyz="0 0 -0.1825"/>
      <geometry>
        <box size="0.3 0.55 0.365"/>
      </geometry>
    </collision>
    <inertial>
      <origin rpy="0 0 0" xyz="0 0 0.15"/>
      <mass value="20"/>
      <inertia ixx="1" ixy="0" ixz="0" iyy="1" iyz="0" izz="1"/>
    </inertial>
  </link>
  <!-- <gazebo reference="linear_axis_sled">
            <self_collide>false</self_collide>
        </gazebo> -->
  <joint name="robot_base_flange" type="fixed">
    <origin rpy="0 0 2.3561946535897933" xyz="0 0 0"/>
    <parent link="linear_axis_sled"/>
    <child link="maira7M_root_link"/>
  </joint>
  <link name="linear_axis_base">
    <visual>
      <origin rpy="0 0 0" xyz="0 0 0.25625"/>
      <geometry>
        <box size="0.35 0.65 0.5125"/>
      </geometry>
      <material name="plastic_glossy_white"/>
    </visual>
    <collision>
      <origin rpy="0 0 0" xyz="0 0 0.25625"/>
      <geometry>
        <box size="0.35 0.65 0.5125"/>
      </geometry>
      <material name="plastic_glossy_white"/>
    </collision>
  </link>
  <joint name="linear_axis_base_joint" type="fixed">
    <origin rpy="0 0 0" xyz="0.52 0 0.3"/>
    <parent link="mav_base_link"/>
    <child link="linear_axis_base"/>
  </joint>
  <material name="blue">
    <color rgba="0 0 0.8 1"/>
  </material>
  <material name="white">
    <color rgba="1 1 1 1"/>
  </material>
  <material name="MelonYellow">
    <color rgba="1.0 0.6 0.0 1.0"/>
  </material>
  <link name="maira7M_root_link"/>
  <joint name="maira7M_root_joint" type="fixed">
    <origin rpy="0 0 1.5708" xyz="0 0 0"/>
    <parent link="maira7M_root_link"/>
    <child link="maira7M_link0"/>
  </joint>
  <link name="maira7M_link0">
    <inertial>
      <mass value="2.133"/>
      <origin rpy="0 0 0" xyz="0.0 0.0 0.0"/>
      <inertia ixx="0.0" ixy="0.0" ixz="0.0" iyy="0.0" iyz="0.0" izz="0.0"/>
    </inertial>
    <visual>
      <origin rpy="0 0 0" xyz="0 0 0"/>
      <geometry>
        <mesh filename="package://mav_description/urdf/maira7M/meshes/Link0_body.stl"/>
      </geometry>
      <material name="white"/>
    </visual>
    <collision>
      <origin rpy="0 0 0" xyz="0 0 0"/>
      <geometry>
        <mesh filename="package://mav_description/urdf/maira7M/collision/Link0_body.stl"/>
      </geometry>
      <material name="white"/>
    </collision>
  </link>
  <joint name="maira7M_joint1" type="revolute">
    <origin rpy="1.5707963267948966 0 0" xyz="0 0 0"/>
    <axis xyz="0 1 0"/>
    <limit effort="432" lower="-3.14159" upper="3.14159" velocity="2.0944"/>
    <parent link="maira7M_link0"/>
    <child link="maira7M_link1"/>
  </joint>
  <link name="maira7M_link1">
    <inertial>
      <mass value="10.458"/>
      <origin rpy="0 0 0" xyz="0.013845 0.316366 0.0"/>
      <inertia ixx="0.1615" ixy="-0.0175" ixz="0.0" iyy="17.5" iyz="0.0" izz="0.1942"/>
    </inertial>
    <visual>
      <origin rpy="0 0 0" xyz="0 0 0"/>
      <geometry>
        <mesh filename="package://mav_description/urdf/maira7M/meshes/Link1_body.stl"/>
      </geometry>
      <material name="white"/>
    </visual>
    <visual>
      <geometry>
        <mesh filename="package://mav_description/urdf/maira7M/meshes/Link1_led.stl"/>
      </geometry>
      <material name="white"/>
    </visual>
    <visual>
      <geometry>
        <mesh filename="package://mav_description/urdf/maira7M/meshes/Link1_ring.stl"/>
      </geometry>
      <material name="white"/>
    </visual>
    <collision>
      <origin rpy="0 0 0" xyz="0 0 0"/>
      <geometry>
        <mesh filename="package://mav_description/urdf/maira7M/collision/Link1_body.stl"/>
      </geometry>
      <material name="white"/>
    </collision>
  </link>
  <joint name="maira7M_joint2" type="revolute">
    <origin rpy="0 0 4.8965276278067904e-12" xyz="0 0.438 0"/>
    <axis xyz="1 0 0"/>
    <limit effort="432" lower="-2.0944" upper="2.0944" velocity="2.0944"/>
    <parent link="maira7M_link1"/>
    <child link="maira7M_link2"/>
  </joint>
  <link name="maira7M_link2">
    <inertial>
      <mass value="14.8"/>
      <origin rpy="0 0 0" xyz="-0.05 0.06 -0.035"/>
      <inertia ixx="17.5" ixy="0.0011" ixz="0.0" iyy="0.1615" iyz="0.0" izz="0.12"/>
    </inertial>
    <visual>
      <origin rpy="0 0 0" xyz="0 0 0"/>
      <geometry>
        <mesh filename="package://mav_description/urdf/maira7M/meshes/Link2_body.stl"/>
      </geometry>
      <material name="white"/>
    </visual>
    <visual>
      <geometry>
        <mesh filename="package://mav_description/urdf/maira7M/meshes/Link2_led.stl"/>
      </geometry>
      <material name="white"/>
    </visual>
    <visual>
      <geometry>
        <mesh filename="package://mav_description/urdf/maira7M/meshes/Link2_ring.stl"/>
      </geometry>
      <material name="white"/>
    </visual>
    <collision>
      <origin rpy="0 0 0" xyz="0 0 0"/>
      <geometry>
        <mesh filename="package://mav_description/urdf/maira7M/collision/Link2_body.stl"/>
      </geometry>
      <material name="white"/>
    </collision>
  </link>
  <joint name="maira7M_joint3" type="revolute">
    <origin rpy="0 0 -4.8965276278067904e-12" xyz="0 0 0"/>
    <axis xyz="0 1 0"/>
    <limit effort="217" lower="-3.14159" upper="3.14159" velocity="2.618"/>
    <parent link="maira7M_link2"/>
    <child link="maira7M_link3"/>
  </joint>
  <link name="maira7M_link3">
    <inertial>
      <mass value="11.0"/>
      <origin rpy="0 0 0" xyz="-0.01 0.45999999999999996 0.0"/>
      <inertia ixx="0.3927" ixy="-0.0251" ixz="0.0" iyy="3.5" iyz="0.0" izz="0.4118"/>
    </inertial>
    <visual>
      <origin rpy="0 0 0" xyz="0 0 0"/>
      <geometry>
        <mesh filename="package://mav_description/urdf/maira7M/meshes/Link3_body.stl"/>
      </geometry>
      <material name="white"/>
    </visual>
    <collision>
      <origin rpy="0 0 0" xyz="0 0 0"/>
      <geometry>
        <mesh filename="package://mav_description/urdf/maira7M/collision/Link3_body.stl"/>
      </geometry>
      <material name="white"/>
    </collision>
  </link>
  <joint name="maira7M_joint4" type="revolute">
    <origin rpy="0 0 4.8965276278067904e-12" xyz="0 0.7 0"/>
    <axis xyz="1 0 0"/>
    <limit effort="217" lower="-2.618" upper="2.618" velocity="2.618"/>
    <parent link="maira7M_link3"/>
    <child link="maira7M_link4"/>
  </joint>
  <link name="maira7M_link4">
    <inertial>
      <mass value="5.5"/>
      <origin rpy="0 0 0" xyz="-0.03 -0.01 0.0"/>
      <inertia ixx="3.5" ixy="0.0006" ixz="0.0" iyy="0.0113" iyz="0.0" izz="0.0215"/>
    </inertial>
    <visual>
      <origin rpy="0 0 0" xyz="0 0 0"/>
      <geometry>
        <mesh filename="package://mav_description/urdf/maira7M/meshes/Link4_body.stl"/>
      </geometry>
      <material name="white"/>
    </visual>
    <visual>
      <origin rpy="0 0 0" xyz="0 0 0"/>
      <geometry>
        <mesh filename="package://mav_description/urdf/maira7M/meshes/Link4_led.stl"/>
      </geometry>
      <material name="white"/>
    </visual>
    <visual>
      <origin rpy="0 0 0" xyz="0 0 0"/>
      <geometry>
        <mesh filename="package://mav_description/urdf/maira7M/meshes/Link4_ring.stl"/>
      </geometry>
      <material name="white"/>
    </visual>
    <collision>
      <origin rpy="0 0 0" xyz="0 0 0"/>
      <geometry>
        <mesh filename="package://mav_description/urdf/maira7M/collision/Link4_body.stl"/>
      </geometry>
      <material name="white"/>
    </collision>
  </link>
  <joint name="maira7M_joint5" type="revolute">
    <origin rpy="0 0 -4.8965276278067904e-12" xyz="0 0 0"/>
    <axis xyz="0 1 0"/>
    <limit effort="57" lower="-3.14159" upper="3.14159" velocity="3.8397"/>
    <parent link="maira7M_link4"/>
    <child link="maira7M_link5"/>
  </joint>
  <link name="maira7M_link5">
    <inertial>
      <mass value="8.0"/>
      <origin rpy="0 0 0" xyz="-0.06 0.36999999999999994 0.0"/>
      <inertia ixx="0.3098" ixy="-0.0624" ixz="0.0" iyy="0.5" iyz="0.0" izz="0.3218"/>
    </inertial>
    <visual>
      <origin rpy="0 0 0" xyz="0 0 0"/>
      <geometry>
        <mesh filename="package://mav_description/urdf/maira7M/meshes/Link5_body.stl"/>
      </geometry>
      <material name="white"/>
    </visual>
    <collision>
      <origin rpy="0 0 0" xyz="0 0 0"/>
      <geometry>
        <mesh filename="package://mav_description/urdf/maira7M/collision/Link5_body.stl"/>
      </geometry>
      <material name="white"/>
    </collision>
  </link>
  <joint name="maira7M_joint6" type="revolute">
    <origin rpy="0 0 4.8965276278067904e-12" xyz="0 0.7 0"/>
    <axis xyz="1 0 0"/>
    <limit effort="57" lower="-3.14159" upper="3.14159" velocity="3.8397"/>
    <parent link="maira7M_link5"/>
    <child link="maira7M_link6"/>
  </joint>
  <link name="maira7M_link6">
    <inertial>
      <mass value="4.5"/>
      <origin rpy="0 0 0" xyz="-0.02 -0.04 -0.01"/>
      <inertia ixx="0.5" ixy="-0.0013" ixz="0.0" iyy="0.0085" iyz="0.0" izz="0.0126"/>
    </inertial>
    <visual>
      <origin rpy="0 0 0" xyz="0 0 0"/>
      <geometry>
        <mesh filename="package://mav_description/urdf/maira7M/meshes/Link6_body.stl"/>
      </geometry>
      <material name="white"/>
    </visual>
    <visual>
      <origin rpy="0 0 0" xyz="0 0 0"/>
      <geometry>
        <mesh filename="package://mav_description/urdf/maira7M/meshes/Link6_led.stl"/>
      </geometry>
      <material name="white"/>
    </visual>
    <visual>
      <origin rpy="0 0 0" xyz="0 0 0"/>
      <geometry>
        <mesh filename="package://mav_description/urdf/maira7M/meshes/Link6_ring.stl"/>
      </geometry>
      <material name="white"/>
    </visual>
    <visual>
      <origin rpy="0 0 0" xyz="0 0 0"/>
      <geometry>
        <mesh filename="package://mav_description/urdf/maira7M/meshes/Link6_sensors.stl"/>
      </geometry>
      <material name="white"/>
    </visual>
    <collision>
      <origin rpy="0 0 0" xyz="0 0 0"/>
      <geometry>
        <mesh filename="package://mav_description/urdf/maira7M/collision/Link6_body.stl"/>
      </geometry>
      <material name="white"/>
    </collision>
  </link>
  <joint name="maira7M_joint7" type="revolute">
    <origin rpy="0 0 -4.8965276278067904e-12" xyz="0 0 0"/>
    <axis xyz="0 1 0"/>
    <limit effort="37" lower="-3.14159" upper="3.14159" velocity="3.14159"/>
    <parent link="maira7M_link6"/>
    <child link="maira7M_link7"/>
  </joint>
  <link name="maira7M_link7">
    <inertial>
      <mass value="1.173"/>
      <origin rpy="0 0 0" xyz="0.0 0.16499999999999998 0.0"/>
      <inertia ixx="0.0024" ixy="0.0" ixz="0.0" iyy="0.3" iyz="0.0" izz="0.0024"/>
    </inertial>
    <visual>
      <origin rpy="0 0 0" xyz="0 0 0"/>
      <geometry>
        <mesh filename="package://mav_description/urdf/maira7M/meshes/Link7_body.stl"/>
      </geometry>
      <material name="white"/>
    </visual>
    <visual>
      <origin rpy="0 0 0" xyz="0 0 0"/>
      <geometry>
        <mesh filename="package://mav_description/urdf/maira7M/meshes/Link7_led.stl"/>
      </geometry>
      <material name="white"/>
    </visual>
    <collision>
      <origin rpy="0 0 0" xyz="0 0 0"/>
      <geometry>
        <mesh filename="package://mav_description/urdf/maira7M/collision/Link7_body.stl"/>
      </geometry>
      <material name="white"/>
    </collision>
  </link>
  <link name="maira7M_flange"/>
  <joint name="maira7M_link7_to_flange" type="fixed">
    <origin rpy="-1.5707963267948966 -1.5707963267948966 0" xyz="0 0.135 0"/>
    <parent link="maira7M_link7"/>
    <child link="maira7M_flange"/>
  </joint>
  <link name="world"/>
  <link name="x_mobile_link"/>
  <joint name="x_mobile_joint" type="prismatic">
    <origin rpy="0 0 0" xyz="0 0 0"/>
    <parent link="world"/>
    <child link="x_mobile_link"/>
    <axis xyz="1 0 0"/>
    <limit effort="100000" lower="-100" upper="100" velocity="0.2"/>
  </joint>
  <link name="y_mobile_link"/>
  <joint name="y_mobile_joint" type="prismatic">
    <origin rpy="0 0 0" xyz="0 0 0"/>
    <parent link="x_mobile_link"/>
    <child link="y_mobile_link"/>
    <axis xyz="0 1 0"/>
    <limit effort="100000" lower="-100" upper="100" velocity="0.2"/>
  </joint>
  <!-- TODO: change the following to continous when Erwin enables that type of joint in the urdf reader -->
  <joint name="theta_mobile_joint" type="revolute">
    <origin rpy="0 0 0" xyz="0 0 0"/>
    <parent link="y_mobile_link"/>
    <child link="mav_base_link"/>
    <axis xyz="0 0 1"/>
    <limit effort="100000" lower="-30" upper="30" velocity="0.3"/>
  </joint>
  <link name="FT_sensor_frame"/>
  <joint name="FT_sensor_frame_joint" type="fixed">
    <parent link="maira7M_flange"/>
    <child link="FT_sensor_frame"/>
    <origin rpy="0.0 0.0 0.0" xyz="0.0 0.0 0.066"/>
  </joint>
  <link name="tool0_grip"/>
  <joint name="tool0_grip_joint" type="fixed">
    <parent link="FT_sensor_frame"/>
    <child link="tool0_grip"/>
    <origin rpy="0.0 0.0 0.0" xyz="0.0 0.0 0.18"/>
  </joint>
  <link name="tool0_cables"/>
  <joint name="tool0_cables_joint" type="fixed">
    <parent link="FT_sensor_frame"/>
    <child link="tool0_cables"/>
    <origin rpy="0.0 3.1416 0.0" xyz="0.0 0.0 0.14"/>
  </joint>
</robot>
